[2024-02-05T09:15:10.258+0000] {taskinstance.py:1171} INFO - Dependencies all met for <TaskInstance: sqlite_randomuser.store_user manual__2024-02-05T09:15:09.187464+00:00 [queued]>
[2024-02-05T09:15:10.273+0000] {taskinstance.py:1171} INFO - Dependencies all met for <TaskInstance: sqlite_randomuser.store_user manual__2024-02-05T09:15:09.187464+00:00 [queued]>
[2024-02-05T09:15:10.274+0000] {taskinstance.py:1368} INFO - 
--------------------------------------------------------------------------------
[2024-02-05T09:15:10.274+0000] {taskinstance.py:1369} INFO - Starting attempt 1 of 1
[2024-02-05T09:15:10.274+0000] {taskinstance.py:1370} INFO - 
--------------------------------------------------------------------------------
[2024-02-05T09:15:10.293+0000] {taskinstance.py:1389} INFO - Executing <Task(SqliteOperator): store_user> on 2024-02-05 09:15:09.187464+00:00
[2024-02-05T09:15:10.300+0000] {standard_task_runner.py:52} INFO - Started process 313064 to run task
[2024-02-05T09:15:10.303+0000] {standard_task_runner.py:79} INFO - Running: ['***', 'tasks', 'run', 'sqlite_randomuser', 'store_user', 'manual__2024-02-05T09:15:09.187464+00:00', '--job-id', '36', '--raw', '--subdir', 'DAGS_FOLDER/sqlite_randomuser.py', '--cfg-path', '/tmp/tmp92yk9cka', '--error-file', '/tmp/tmphn12pdxw']
[2024-02-05T09:15:10.305+0000] {standard_task_runner.py:80} INFO - Job 36: Subtask store_user
[2024-02-05T09:15:10.379+0000] {task_command.py:371} INFO - Running <TaskInstance: sqlite_randomuser.store_user manual__2024-02-05T09:15:09.187464+00:00 [running]> on host fe2863c78e2f
[2024-02-05T09:15:10.477+0000] {taskinstance.py:1583} INFO - Exporting the following env vars:
AIRFLOW_CTX_DAG_OWNER=***
AIRFLOW_CTX_DAG_ID=sqlite_randomuser
AIRFLOW_CTX_TASK_ID=store_user
AIRFLOW_CTX_EXECUTION_DATE=2024-02-05T09:15:09.187464+00:00
AIRFLOW_CTX_TRY_NUMBER=1
AIRFLOW_CTX_DAG_RUN_ID=manual__2024-02-05T09:15:09.187464+00:00
[2024-02-05T09:15:10.478+0000] {sqlite.py:59} INFO - Executing: 
            INSERT INTO users (firstname, lastname, country, username, password, email)
            VALUES (:firstname, :lastname, :country, :username, :password, :email)
        
[2024-02-05T09:15:10.489+0000] {base.py:68} INFO - Using connection ID 'sql_lite' for task execution.
[2024-02-05T09:15:10.491+0000] {sql.py:315} INFO - Running statement: INSERT INTO users (firstname, lastname, country, username, password, email)
            VALUES (:firstname, :lastname, :country, :username, :password, :email), parameters: {'firstname': '{{ task_instance.xcom_pull(task_ids="process_user", key="name.first", include_prior_dates=True) }}', 'lastname': '{{ task_instance.xcom_pull(task_ids="process_user", key="name.first", include_prior_dates=True) }}', 'country': '{{ task_instance.xcom_pull(task_ids="process_user", key="country", include_prior_dates=True) }}', 'username': '{{ task_instance.xcom_pull(task_ids="process_user", key="login.username", include_prior_dates=True) }}', 'password': '***', 'email': '{{ task_instance.xcom_pull(task_ids="process_user", key="email", include_prior_dates=True) }}'}
[2024-02-05T09:15:10.492+0000] {taskinstance.py:1902} ERROR - Task failed with exception
Traceback (most recent call last):
  File "/home/airflow/.local/lib/python3.7/site-packages/airflow/providers/sqlite/operators/sqlite.py", line 61, in execute
    hook.run(self.sql, parameters=self.parameters)
  File "/home/airflow/.local/lib/python3.7/site-packages/airflow/providers/common/sql/hooks/sql.py", line 295, in run
    self._run_command(cur, sql_statement, parameters)
  File "/home/airflow/.local/lib/python3.7/site-packages/airflow/providers/common/sql/hooks/sql.py", line 318, in _run_command
    cur.execute(sql_statement, parameters)
sqlite3.OperationalError: no such table: users
[2024-02-05T09:15:10.504+0000] {taskinstance.py:1412} INFO - Marking task as FAILED. dag_id=sqlite_randomuser, task_id=store_user, execution_date=20240205T091509, start_date=20240205T091510, end_date=20240205T091510
[2024-02-05T09:15:10.519+0000] {standard_task_runner.py:97} ERROR - Failed to execute job 36 for task store_user (no such table: users; 313064)
[2024-02-05T09:15:10.565+0000] {local_task_job.py:156} INFO - Task exited with return code 1
[2024-02-05T09:15:10.603+0000] {local_task_job.py:279} INFO - 0 downstream tasks scheduled from follow-on schedule check
