[2024-02-05T20:31:25.374+0000] {taskinstance.py:1171} INFO - Dependencies all met for <TaskInstance: sqlite_randomuser.processing_user manual__2024-02-05T20:31:19.078968+00:00 [queued]>
[2024-02-05T20:31:25.386+0000] {taskinstance.py:1171} INFO - Dependencies all met for <TaskInstance: sqlite_randomuser.processing_user manual__2024-02-05T20:31:19.078968+00:00 [queued]>
[2024-02-05T20:31:25.386+0000] {taskinstance.py:1368} INFO - 
--------------------------------------------------------------------------------
[2024-02-05T20:31:25.387+0000] {taskinstance.py:1369} INFO - Starting attempt 1 of 1
[2024-02-05T20:31:25.387+0000] {taskinstance.py:1370} INFO - 
--------------------------------------------------------------------------------
[2024-02-05T20:31:25.403+0000] {taskinstance.py:1389} INFO - Executing <Task(PythonOperator): processing_user> on 2024-02-05 20:31:19.078968+00:00
[2024-02-05T20:31:25.410+0000] {standard_task_runner.py:52} INFO - Started process 339602 to run task
[2024-02-05T20:31:25.412+0000] {standard_task_runner.py:79} INFO - Running: ['***', 'tasks', 'run', 'sqlite_randomuser', 'processing_user', 'manual__2024-02-05T20:31:19.078968+00:00', '--job-id', '54', '--raw', '--subdir', 'DAGS_FOLDER/sqlite_randomuser.py', '--cfg-path', '/tmp/tmpnfvnj_b1', '--error-file', '/tmp/tmpmzmkmbxz']
[2024-02-05T20:31:25.413+0000] {standard_task_runner.py:80} INFO - Job 54: Subtask processing_user
[2024-02-05T20:31:25.478+0000] {task_command.py:371} INFO - Running <TaskInstance: sqlite_randomuser.processing_user manual__2024-02-05T20:31:19.078968+00:00 [running]> on host fe2863c78e2f
[2024-02-05T20:31:25.571+0000] {taskinstance.py:1583} INFO - Exporting the following env vars:
AIRFLOW_CTX_DAG_OWNER=***
AIRFLOW_CTX_DAG_ID=sqlite_randomuser
AIRFLOW_CTX_TASK_ID=processing_user
AIRFLOW_CTX_EXECUTION_DATE=2024-02-05T20:31:19.078968+00:00
AIRFLOW_CTX_TRY_NUMBER=1
AIRFLOW_CTX_DAG_RUN_ID=manual__2024-02-05T20:31:19.078968+00:00
[2024-02-05T20:31:25.573+0000] {taskinstance.py:1902} ERROR - Task failed with exception
Traceback (most recent call last):
  File "/home/airflow/.local/lib/python3.7/site-packages/airflow/operators/python.py", line 171, in execute
    return_value = self.execute_callable()
  File "/home/airflow/.local/lib/python3.7/site-packages/airflow/operators/python.py", line 189, in execute_callable
    return self.python_callable(*self.op_args, **self.op_kwargs)
TypeError: process_user() takes 0 positional arguments but 1 was given
[2024-02-05T20:31:25.583+0000] {taskinstance.py:1412} INFO - Marking task as FAILED. dag_id=sqlite_randomuser, task_id=processing_user, execution_date=20240205T203119, start_date=20240205T203125, end_date=20240205T203125
[2024-02-05T20:31:25.597+0000] {standard_task_runner.py:97} ERROR - Failed to execute job 54 for task processing_user (process_user() takes 0 positional arguments but 1 was given; 339602)
[2024-02-05T20:31:25.625+0000] {local_task_job.py:156} INFO - Task exited with return code 1
[2024-02-05T20:31:25.661+0000] {local_task_job.py:279} INFO - 0 downstream tasks scheduled from follow-on schedule check
