[2024-02-06T03:44:39.688+0000] {taskinstance.py:1171} INFO - Dependencies all met for <TaskInstance: nyctaxi_elt.fetch_data manual__2024-02-06T03:44:36.912845+00:00 [queued]>
[2024-02-06T03:44:39.698+0000] {taskinstance.py:1171} INFO - Dependencies all met for <TaskInstance: nyctaxi_elt.fetch_data manual__2024-02-06T03:44:36.912845+00:00 [queued]>
[2024-02-06T03:44:39.698+0000] {taskinstance.py:1368} INFO - 
--------------------------------------------------------------------------------
[2024-02-06T03:44:39.699+0000] {taskinstance.py:1369} INFO - Starting attempt 1 of 1
[2024-02-06T03:44:39.699+0000] {taskinstance.py:1370} INFO - 
--------------------------------------------------------------------------------
[2024-02-06T03:44:39.713+0000] {taskinstance.py:1389} INFO - Executing <Task(PythonOperator): fetch_data> on 2024-02-06 03:44:36.912845+00:00
[2024-02-06T03:44:39.723+0000] {standard_task_runner.py:52} INFO - Started process 1616 to run task
[2024-02-06T03:44:39.725+0000] {standard_task_runner.py:79} INFO - Running: ['***', 'tasks', 'run', 'nyctaxi_elt', 'fetch_data', 'manual__2024-02-06T03:44:36.912845+00:00', '--job-id', '8', '--raw', '--subdir', 'DAGS_FOLDER/nyctaxi_elt.py', '--cfg-path', '/tmp/tmpczjjv54p', '--error-file', '/tmp/tmpoo1u7b1e']
[2024-02-06T03:44:39.726+0000] {standard_task_runner.py:80} INFO - Job 8: Subtask fetch_data
[2024-02-06T03:44:39.797+0000] {task_command.py:371} INFO - Running <TaskInstance: nyctaxi_elt.fetch_data manual__2024-02-06T03:44:36.912845+00:00 [running]> on host 9d3dd91d9998
[2024-02-06T03:44:39.869+0000] {taskinstance.py:1583} INFO - Exporting the following env vars:
AIRFLOW_CTX_DAG_OWNER=***
AIRFLOW_CTX_DAG_ID=nyctaxi_elt
AIRFLOW_CTX_TASK_ID=fetch_data
AIRFLOW_CTX_EXECUTION_DATE=2024-02-06T03:44:36.912845+00:00
AIRFLOW_CTX_TRY_NUMBER=1
AIRFLOW_CTX_DAG_RUN_ID=manual__2024-02-06T03:44:36.912845+00:00
[2024-02-06T03:44:41.411+0000] {taskinstance.py:1902} ERROR - Task failed with exception
Traceback (most recent call last):
  File "/home/airflow/.local/lib/python3.7/site-packages/airflow/operators/python.py", line 171, in execute
    return_value = self.execute_callable()
  File "/home/airflow/.local/lib/python3.7/site-packages/airflow/operators/python.py", line 189, in execute_callable
    return self.python_callable(*self.op_args, **self.op_kwargs)
  File "/opt/airflow/dags/nyctaxi_elt.py", line 47, in fetch_data
    processed_data = pd.Dataframe(data)
  File "/home/airflow/.local/lib/python3.7/site-packages/pandas/__init__.py", line 244, in __getattr__
    raise AttributeError(f"module 'pandas' has no attribute '{name}'")
AttributeError: module 'pandas' has no attribute 'Dataframe'
[2024-02-06T03:44:41.425+0000] {taskinstance.py:1412} INFO - Marking task as FAILED. dag_id=nyctaxi_elt, task_id=fetch_data, execution_date=20240206T034436, start_date=20240206T034439, end_date=20240206T034441
[2024-02-06T03:44:41.435+0000] {standard_task_runner.py:97} ERROR - Failed to execute job 8 for task fetch_data (module 'pandas' has no attribute 'Dataframe'; 1616)
[2024-02-06T03:44:41.465+0000] {local_task_job.py:156} INFO - Task exited with return code 1
[2024-02-06T03:44:41.495+0000] {local_task_job.py:279} INFO - 0 downstream tasks scheduled from follow-on schedule check
