[2024-02-06T04:14:16.454+0000] {taskinstance.py:1171} INFO - Dependencies all met for <TaskInstance: nyctaxi_elt.insert_data manual__2024-02-06T04:14:11.843017+00:00 [queued]>
[2024-02-06T04:14:16.465+0000] {taskinstance.py:1171} INFO - Dependencies all met for <TaskInstance: nyctaxi_elt.insert_data manual__2024-02-06T04:14:11.843017+00:00 [queued]>
[2024-02-06T04:14:16.465+0000] {taskinstance.py:1368} INFO - 
--------------------------------------------------------------------------------
[2024-02-06T04:14:16.466+0000] {taskinstance.py:1369} INFO - Starting attempt 1 of 1
[2024-02-06T04:14:16.466+0000] {taskinstance.py:1370} INFO - 
--------------------------------------------------------------------------------
[2024-02-06T04:14:16.478+0000] {taskinstance.py:1389} INFO - Executing <Task(PythonOperator): insert_data> on 2024-02-06 04:14:11.843017+00:00
[2024-02-06T04:14:16.486+0000] {standard_task_runner.py:52} INFO - Started process 2636 to run task
[2024-02-06T04:14:16.488+0000] {standard_task_runner.py:79} INFO - Running: ['***', 'tasks', 'run', 'nyctaxi_elt', 'insert_data', 'manual__2024-02-06T04:14:11.843017+00:00', '--job-id', '31', '--raw', '--subdir', 'DAGS_FOLDER/nyctaxi_elt.py', '--cfg-path', '/tmp/tmpmn287d3a', '--error-file', '/tmp/tmp3p5ak6lr']
[2024-02-06T04:14:16.489+0000] {standard_task_runner.py:80} INFO - Job 31: Subtask insert_data
[2024-02-06T04:14:16.543+0000] {task_command.py:371} INFO - Running <TaskInstance: nyctaxi_elt.insert_data manual__2024-02-06T04:14:11.843017+00:00 [running]> on host 9d3dd91d9998
[2024-02-06T04:14:16.608+0000] {taskinstance.py:1583} INFO - Exporting the following env vars:
AIRFLOW_CTX_DAG_OWNER=***
AIRFLOW_CTX_DAG_ID=nyctaxi_elt
AIRFLOW_CTX_TASK_ID=insert_data
AIRFLOW_CTX_EXECUTION_DATE=2024-02-06T04:14:11.843017+00:00
AIRFLOW_CTX_TRY_NUMBER=1
AIRFLOW_CTX_DAG_RUN_ID=manual__2024-02-06T04:14:11.843017+00:00
[2024-02-06T04:14:16.656+0000] {taskinstance.py:1902} ERROR - Task failed with exception
Traceback (most recent call last):
  File "/home/airflow/.local/lib/python3.7/site-packages/airflow/operators/python.py", line 171, in execute
    return_value = self.execute_callable()
  File "/home/airflow/.local/lib/python3.7/site-packages/airflow/operators/python.py", line 189, in execute_callable
    return self.python_callable(*self.op_args, **self.op_kwargs)
  File "/opt/airflow/dags/nyctaxi_elt.py", line 63, in clean_and_insert
    insert_to_postgres(cleaned_df)
  File "/opt/airflow/dags/nyctaxi_elt.py", line 124, in insert_to_postgres
    row['congestion_surcharge']
psycopg2.errors.UndefinedTable: relation "your_table_name" does not exist
LINE 1: INSERT INTO your_table_name (vendorid, lpep_pickup_datetime,...
                    ^

[2024-02-06T04:14:16.668+0000] {taskinstance.py:1412} INFO - Marking task as FAILED. dag_id=nyctaxi_elt, task_id=insert_data, execution_date=20240206T041411, start_date=20240206T041416, end_date=20240206T041416
[2024-02-06T04:14:16.677+0000] {standard_task_runner.py:97} ERROR - Failed to execute job 31 for task insert_data (relation "your_table_name" does not exist
LINE 1: INSERT INTO your_table_name (vendorid, lpep_pickup_datetime,...
                    ^
; 2636)
[2024-02-06T04:14:16.701+0000] {local_task_job.py:156} INFO - Task exited with return code 1
[2024-02-06T04:14:16.734+0000] {local_task_job.py:279} INFO - 0 downstream tasks scheduled from follow-on schedule check
