[2024-02-05T07:10:50.918+0000] {taskinstance.py:1171} INFO - Dependencies all met for <TaskInstance: sqlite_randomuser.is_api_available manual__2024-02-05T07:10:48.852124+00:00 [queued]>
[2024-02-05T07:10:50.930+0000] {taskinstance.py:1171} INFO - Dependencies all met for <TaskInstance: sqlite_randomuser.is_api_available manual__2024-02-05T07:10:48.852124+00:00 [queued]>
[2024-02-05T07:10:50.930+0000] {taskinstance.py:1368} INFO - 
--------------------------------------------------------------------------------
[2024-02-05T07:10:50.931+0000] {taskinstance.py:1369} INFO - Starting attempt 1 of 1
[2024-02-05T07:10:50.932+0000] {taskinstance.py:1370} INFO - 
--------------------------------------------------------------------------------
[2024-02-05T07:10:50.945+0000] {taskinstance.py:1389} INFO - Executing <Task(HttpSensor): is_api_available> on 2024-02-05 07:10:48.852124+00:00
[2024-02-05T07:10:50.951+0000] {standard_task_runner.py:52} INFO - Started process 27805 to run task
[2024-02-05T07:10:50.953+0000] {standard_task_runner.py:79} INFO - Running: ['***', 'tasks', 'run', 'sqlite_randomuser', 'is_api_available', 'manual__2024-02-05T07:10:48.852124+00:00', '--job-id', '7', '--raw', '--subdir', 'DAGS_FOLDER/sqlite_randomuser.py', '--cfg-path', '/tmp/tmpy8369n49', '--error-file', '/tmp/tmpheyxlopx']
[2024-02-05T07:10:50.955+0000] {standard_task_runner.py:80} INFO - Job 7: Subtask is_api_available
[2024-02-05T07:10:51.017+0000] {task_command.py:371} INFO - Running <TaskInstance: sqlite_randomuser.is_api_available manual__2024-02-05T07:10:48.852124+00:00 [running]> on host fe2863c78e2f
[2024-02-05T07:10:51.091+0000] {taskinstance.py:1583} INFO - Exporting the following env vars:
AIRFLOW_CTX_DAG_OWNER=***
AIRFLOW_CTX_DAG_ID=sqlite_randomuser
AIRFLOW_CTX_TASK_ID=is_api_available
AIRFLOW_CTX_EXECUTION_DATE=2024-02-05T07:10:48.852124+00:00
AIRFLOW_CTX_TRY_NUMBER=1
AIRFLOW_CTX_DAG_RUN_ID=manual__2024-02-05T07:10:48.852124+00:00
[2024-02-05T07:10:51.092+0000] {http.py:120} INFO - Poking: api/
[2024-02-05T07:10:51.102+0000] {base.py:68} INFO - Using connection ID 'randomuser_api' for task execution.
[2024-02-05T07:10:51.105+0000] {http.py:148} INFO - Sending 'GET' to url: http://api/
[2024-02-05T07:10:52.276+0000] {http.py:206} WARNING - HTTPConnectionPool(host='api', port=80): Max retries exceeded with url: / (Caused by NewConnectionError('<urllib3.connection.HTTPConnection object at 0x7f3cc3560b50>: Failed to establish a new connection: [Errno -2] Name or service not known')) Tenacity will retry to execute the operation
[2024-02-05T07:10:52.277+0000] {taskinstance.py:1902} ERROR - Task failed with exception
Traceback (most recent call last):
  File "/home/airflow/.local/lib/python3.7/site-packages/urllib3/connection.py", line 175, in _new_conn
    (self._dns_host, self.port), self.timeout, **extra_kw
  File "/home/airflow/.local/lib/python3.7/site-packages/urllib3/util/connection.py", line 72, in create_connection
    for res in socket.getaddrinfo(host, port, family, socket.SOCK_STREAM):
  File "/usr/local/lib/python3.7/socket.py", line 752, in getaddrinfo
    for res in _socket.getaddrinfo(host, port, family, type, proto, flags):
socket.gaierror: [Errno -2] Name or service not known

During handling of the above exception, another exception occurred:

Traceback (most recent call last):
  File "/home/airflow/.local/lib/python3.7/site-packages/urllib3/connectionpool.py", line 710, in urlopen
    chunked=chunked,
  File "/home/airflow/.local/lib/python3.7/site-packages/urllib3/connectionpool.py", line 398, in _make_request
    conn.request(method, url, **httplib_request_kw)
  File "/home/airflow/.local/lib/python3.7/site-packages/urllib3/connection.py", line 239, in request
    super(HTTPConnection, self).request(method, url, body=body, headers=headers)
  File "/usr/local/lib/python3.7/http/client.py", line 1281, in request
    self._send_request(method, url, body, headers, encode_chunked)
  File "/usr/local/lib/python3.7/http/client.py", line 1327, in _send_request
    self.endheaders(body, encode_chunked=encode_chunked)
  File "/usr/local/lib/python3.7/http/client.py", line 1276, in endheaders
    self._send_output(message_body, encode_chunked=encode_chunked)
  File "/usr/local/lib/python3.7/http/client.py", line 1036, in _send_output
    self.send(msg)
  File "/usr/local/lib/python3.7/http/client.py", line 976, in send
    self.connect()
  File "/home/airflow/.local/lib/python3.7/site-packages/urllib3/connection.py", line 205, in connect
    conn = self._new_conn()
  File "/home/airflow/.local/lib/python3.7/site-packages/urllib3/connection.py", line 187, in _new_conn
    self, "Failed to establish a new connection: %s" % e
urllib3.exceptions.NewConnectionError: <urllib3.connection.HTTPConnection object at 0x7f3cc3560b50>: Failed to establish a new connection: [Errno -2] Name or service not known

During handling of the above exception, another exception occurred:

Traceback (most recent call last):
  File "/home/airflow/.local/lib/python3.7/site-packages/requests/adapters.py", line 499, in send
    timeout=timeout,
  File "/home/airflow/.local/lib/python3.7/site-packages/urllib3/connectionpool.py", line 788, in urlopen
    method, url, error=e, _pool=self, _stacktrace=sys.exc_info()[2]
  File "/home/airflow/.local/lib/python3.7/site-packages/urllib3/util/retry.py", line 592, in increment
    raise MaxRetryError(_pool, url, error or ResponseError(cause))
urllib3.exceptions.MaxRetryError: HTTPConnectionPool(host='api', port=80): Max retries exceeded with url: / (Caused by NewConnectionError('<urllib3.connection.HTTPConnection object at 0x7f3cc3560b50>: Failed to establish a new connection: [Errno -2] Name or service not known'))

During handling of the above exception, another exception occurred:

Traceback (most recent call last):
  File "/home/airflow/.local/lib/python3.7/site-packages/airflow/sensors/base.py", line 277, in execute
    poke_return = self.poke(context)
  File "/home/airflow/.local/lib/python3.7/site-packages/airflow/providers/http/sensors/http.py", line 126, in poke
    extra_options=self.extra_options,
  File "/home/airflow/.local/lib/python3.7/site-packages/airflow/providers/http/hooks/http.py", line 149, in run
    return self.run_and_check(session, prepped_request, extra_options)
  File "/home/airflow/.local/lib/python3.7/site-packages/airflow/providers/http/hooks/http.py", line 207, in run_and_check
    raise ex
  File "/home/airflow/.local/lib/python3.7/site-packages/airflow/providers/http/hooks/http.py", line 199, in run_and_check
    response = session.send(prepped_request, **send_kwargs)
  File "/home/airflow/.local/lib/python3.7/site-packages/requests/sessions.py", line 701, in send
    r = adapter.send(request, **kwargs)
  File "/home/airflow/.local/lib/python3.7/site-packages/requests/adapters.py", line 565, in send
    raise ConnectionError(e, request=request)
requests.exceptions.ConnectionError: HTTPConnectionPool(host='api', port=80): Max retries exceeded with url: / (Caused by NewConnectionError('<urllib3.connection.HTTPConnection object at 0x7f3cc3560b50>: Failed to establish a new connection: [Errno -2] Name or service not known'))
[2024-02-05T07:10:52.290+0000] {taskinstance.py:1412} INFO - Marking task as FAILED. dag_id=sqlite_randomuser, task_id=is_api_available, execution_date=20240205T071048, start_date=20240205T071050, end_date=20240205T071052
[2024-02-05T07:10:52.302+0000] {standard_task_runner.py:97} ERROR - Failed to execute job 7 for task is_api_available (HTTPConnectionPool(host='api', port=80): Max retries exceeded with url: / (Caused by NewConnectionError('<urllib3.connection.HTTPConnection object at 0x7f3cc3560b50>: Failed to establish a new connection: [Errno -2] Name or service not known')); 27805)
[2024-02-05T07:10:52.324+0000] {local_task_job.py:156} INFO - Task exited with return code 1
[2024-02-05T07:10:52.355+0000] {local_task_job.py:279} INFO - 0 downstream tasks scheduled from follow-on schedule check
