[2024-02-05T09:24:41.455+0000] {taskinstance.py:1171} INFO - Dependencies all met for <TaskInstance: sqlite_randomuser.store_user manual__2024-02-05T09:24:40.002274+00:00 [queued]>
[2024-02-05T09:24:41.477+0000] {taskinstance.py:1171} INFO - Dependencies all met for <TaskInstance: sqlite_randomuser.store_user manual__2024-02-05T09:24:40.002274+00:00 [queued]>
[2024-02-05T09:24:41.478+0000] {taskinstance.py:1368} INFO - 
--------------------------------------------------------------------------------
[2024-02-05T09:24:41.478+0000] {taskinstance.py:1369} INFO - Starting attempt 1 of 1
[2024-02-05T09:24:41.479+0000] {taskinstance.py:1370} INFO - 
--------------------------------------------------------------------------------
[2024-02-05T09:24:41.504+0000] {taskinstance.py:1389} INFO - Executing <Task(BashOperator): store_user> on 2024-02-05 09:24:40.002274+00:00
[2024-02-05T09:24:41.512+0000] {standard_task_runner.py:52} INFO - Started process 330045 to run task
[2024-02-05T09:24:41.516+0000] {standard_task_runner.py:79} INFO - Running: ['***', 'tasks', 'run', 'sqlite_randomuser', 'store_user', 'manual__2024-02-05T09:24:40.002274+00:00', '--job-id', '47', '--raw', '--subdir', 'DAGS_FOLDER/sqlite_randomuser.py', '--cfg-path', '/tmp/tmpx3zt9m_x', '--error-file', '/tmp/tmpy2may1yk']
[2024-02-05T09:24:41.518+0000] {standard_task_runner.py:80} INFO - Job 47: Subtask store_user
[2024-02-05T09:24:41.622+0000] {task_command.py:371} INFO - Running <TaskInstance: sqlite_randomuser.store_user manual__2024-02-05T09:24:40.002274+00:00 [running]> on host fe2863c78e2f
[2024-02-05T09:24:41.856+0000] {taskinstance.py:1583} INFO - Exporting the following env vars:
AIRFLOW_CTX_DAG_OWNER=***
AIRFLOW_CTX_DAG_ID=sqlite_randomuser
AIRFLOW_CTX_TASK_ID=store_user
AIRFLOW_CTX_EXECUTION_DATE=2024-02-05T09:24:40.002274+00:00
AIRFLOW_CTX_TRY_NUMBER=1
AIRFLOW_CTX_DAG_RUN_ID=manual__2024-02-05T09:24:40.002274+00:00
[2024-02-05T09:24:41.860+0000] {subprocess.py:62} INFO - Tmp dir root location: 
 /tmp
[2024-02-05T09:24:41.862+0000] {subprocess.py:74} INFO - Running command: ['/bin/bash', '-c', 'echo "INSERT INTO users (firstname, lastname, country, username, password, email) VALUES (None, None, None, None, None, None);" | sqlite3 ***.db']
[2024-02-05T09:24:41.883+0000] {subprocess.py:85} INFO - Output:
[2024-02-05T09:24:41.961+0000] {subprocess.py:92} INFO - Error: near line 1: no such table: users
[2024-02-05T09:24:41.962+0000] {subprocess.py:96} INFO - Command exited with return code 1
[2024-02-05T09:24:41.991+0000] {taskinstance.py:1902} ERROR - Task failed with exception
Traceback (most recent call last):
  File "/home/airflow/.local/lib/python3.7/site-packages/airflow/operators/bash.py", line 197, in execute
    f'Bash command failed. The command returned a non-zero exit code {result.exit_code}.'
airflow.exceptions.AirflowException: Bash command failed. The command returned a non-zero exit code 1.
[2024-02-05T09:24:41.999+0000] {taskinstance.py:1412} INFO - Marking task as FAILED. dag_id=sqlite_randomuser, task_id=store_user, execution_date=20240205T092440, start_date=20240205T092441, end_date=20240205T092441
[2024-02-05T09:24:42.021+0000] {standard_task_runner.py:97} ERROR - Failed to execute job 47 for task store_user (Bash command failed. The command returned a non-zero exit code 1.; 330045)
[2024-02-05T09:24:42.034+0000] {local_task_job.py:156} INFO - Task exited with return code 1
[2024-02-05T09:24:42.086+0000] {local_task_job.py:279} INFO - 0 downstream tasks scheduled from follow-on schedule check
