[2024-02-05T09:21:43.845+0000] {taskinstance.py:1171} INFO - Dependencies all met for <TaskInstance: sqlite_randomuser.store_user manual__2024-02-05T09:21:42.132520+00:00 [queued]>
[2024-02-05T09:21:43.862+0000] {taskinstance.py:1171} INFO - Dependencies all met for <TaskInstance: sqlite_randomuser.store_user manual__2024-02-05T09:21:42.132520+00:00 [queued]>
[2024-02-05T09:21:43.863+0000] {taskinstance.py:1368} INFO - 
--------------------------------------------------------------------------------
[2024-02-05T09:21:43.863+0000] {taskinstance.py:1369} INFO - Starting attempt 1 of 1
[2024-02-05T09:21:43.864+0000] {taskinstance.py:1370} INFO - 
--------------------------------------------------------------------------------
[2024-02-05T09:21:43.891+0000] {taskinstance.py:1389} INFO - Executing <Task(SqliteOperator): store_user> on 2024-02-05 09:21:42.132520+00:00
[2024-02-05T09:21:43.899+0000] {standard_task_runner.py:52} INFO - Started process 326374 to run task
[2024-02-05T09:21:43.903+0000] {standard_task_runner.py:79} INFO - Running: ['***', 'tasks', 'run', 'sqlite_randomuser', 'store_user', 'manual__2024-02-05T09:21:42.132520+00:00', '--job-id', '42', '--raw', '--subdir', 'DAGS_FOLDER/sqlite_randomuser.py', '--cfg-path', '/tmp/tmpkvcsaq1a', '--error-file', '/tmp/tmpruggquc1']
[2024-02-05T09:21:43.905+0000] {standard_task_runner.py:80} INFO - Job 42: Subtask store_user
[2024-02-05T09:21:44.023+0000] {task_command.py:371} INFO - Running <TaskInstance: sqlite_randomuser.store_user manual__2024-02-05T09:21:42.132520+00:00 [running]> on host fe2863c78e2f
[2024-02-05T09:21:44.230+0000] {taskinstance.py:1583} INFO - Exporting the following env vars:
AIRFLOW_CTX_DAG_OWNER=***
AIRFLOW_CTX_DAG_ID=sqlite_randomuser
AIRFLOW_CTX_TASK_ID=store_user
AIRFLOW_CTX_EXECUTION_DATE=2024-02-05T09:21:42.132520+00:00
AIRFLOW_CTX_TRY_NUMBER=1
AIRFLOW_CTX_DAG_RUN_ID=manual__2024-02-05T09:21:42.132520+00:00
[2024-02-05T09:21:44.234+0000] {sqlite.py:59} INFO - Executing: 
            INSERT INTO users (firstname, lastname, country, username, password, email)
            VALUES (:firstname, :lastname, :country, :username, :password, :email)
        
[2024-02-05T09:21:44.252+0000] {base.py:68} INFO - Using connection ID 'sql_lite' for task execution.
[2024-02-05T09:21:44.253+0000] {sql.py:315} INFO - Running statement: INSERT INTO users (firstname, lastname, country, username, password, email)
            VALUES (:firstname, :lastname, :country, :username, :password, :email), parameters: {'firstname': '{{ task_instance.xcom_pull(task_ids="processing_user", key="name.first", include_prior_dates=True) }}', 'lastname': '{{ task_instance.xcom_pull(task_ids="processing_user", key="name.first", include_prior_dates=True) }}', 'country': '{{ task_instance.xcom_pull(task_ids="processing_user", key="country", include_prior_dates=True) }}', 'username': '{{ task_instance.xcom_pull(task_ids="processing_user", key="login.username", include_prior_dates=True) }}', 'password': '***', 'email': '{{ task_instance.xcom_pull(task_ids="processing_user", key="email", include_prior_dates=True) }}'}
[2024-02-05T09:21:44.255+0000] {taskinstance.py:1902} ERROR - Task failed with exception
Traceback (most recent call last):
  File "/home/airflow/.local/lib/python3.7/site-packages/airflow/providers/sqlite/operators/sqlite.py", line 61, in execute
    hook.run(self.sql, parameters=self.parameters)
  File "/home/airflow/.local/lib/python3.7/site-packages/airflow/providers/common/sql/hooks/sql.py", line 295, in run
    self._run_command(cur, sql_statement, parameters)
  File "/home/airflow/.local/lib/python3.7/site-packages/airflow/providers/common/sql/hooks/sql.py", line 318, in _run_command
    cur.execute(sql_statement, parameters)
sqlite3.OperationalError: no such table: users
[2024-02-05T09:21:44.271+0000] {taskinstance.py:1412} INFO - Marking task as FAILED. dag_id=sqlite_randomuser, task_id=store_user, execution_date=20240205T092142, start_date=20240205T092143, end_date=20240205T092144
[2024-02-05T09:21:44.292+0000] {standard_task_runner.py:97} ERROR - Failed to execute job 42 for task store_user (no such table: users; 326374)
[2024-02-05T09:21:44.323+0000] {local_task_job.py:156} INFO - Task exited with return code 1
[2024-02-05T09:21:44.380+0000] {local_task_job.py:279} INFO - 0 downstream tasks scheduled from follow-on schedule check
