[2024-02-05T07:09:47.014+0000] {taskinstance.py:1171} INFO - Dependencies all met for <TaskInstance: sqlite_randomuser.is_api_available scheduled__2024-02-04T00:00:00+00:00 [queued]>
[2024-02-05T07:09:47.029+0000] {taskinstance.py:1171} INFO - Dependencies all met for <TaskInstance: sqlite_randomuser.is_api_available scheduled__2024-02-04T00:00:00+00:00 [queued]>
[2024-02-05T07:09:47.030+0000] {taskinstance.py:1368} INFO - 
--------------------------------------------------------------------------------
[2024-02-05T07:09:47.030+0000] {taskinstance.py:1369} INFO - Starting attempt 1 of 1
[2024-02-05T07:09:47.031+0000] {taskinstance.py:1370} INFO - 
--------------------------------------------------------------------------------
[2024-02-05T07:09:47.045+0000] {taskinstance.py:1389} INFO - Executing <Task(HttpSensor): is_api_available> on 2024-02-04 00:00:00+00:00
[2024-02-05T07:09:47.051+0000] {standard_task_runner.py:52} INFO - Started process 25977 to run task
[2024-02-05T07:09:47.053+0000] {standard_task_runner.py:79} INFO - Running: ['***', 'tasks', 'run', 'sqlite_randomuser', 'is_api_available', 'scheduled__2024-02-04T00:00:00+00:00', '--job-id', '3', '--raw', '--subdir', 'DAGS_FOLDER/sqlite_randomuser.py', '--cfg-path', '/tmp/tmpbconf0oo', '--error-file', '/tmp/tmp1m0relhp']
[2024-02-05T07:09:47.054+0000] {standard_task_runner.py:80} INFO - Job 3: Subtask is_api_available
[2024-02-05T07:09:47.108+0000] {task_command.py:371} INFO - Running <TaskInstance: sqlite_randomuser.is_api_available scheduled__2024-02-04T00:00:00+00:00 [running]> on host fe2863c78e2f
[2024-02-05T07:09:47.177+0000] {taskinstance.py:1583} INFO - Exporting the following env vars:
AIRFLOW_CTX_DAG_OWNER=***
AIRFLOW_CTX_DAG_ID=sqlite_randomuser
AIRFLOW_CTX_TASK_ID=is_api_available
AIRFLOW_CTX_EXECUTION_DATE=2024-02-04T00:00:00+00:00
AIRFLOW_CTX_TRY_NUMBER=1
AIRFLOW_CTX_DAG_RUN_ID=scheduled__2024-02-04T00:00:00+00:00
[2024-02-05T07:09:47.178+0000] {http.py:120} INFO - Poking: api/
[2024-02-05T07:09:47.199+0000] {taskinstance.py:1902} ERROR - Task failed with exception
Traceback (most recent call last):
  File "/home/airflow/.local/lib/python3.7/site-packages/airflow/sensors/base.py", line 277, in execute
    poke_return = self.poke(context)
  File "/home/airflow/.local/lib/python3.7/site-packages/airflow/providers/http/sensors/http.py", line 135, in poke
    raise exc
  File "/home/airflow/.local/lib/python3.7/site-packages/airflow/providers/http/sensors/http.py", line 126, in poke
    extra_options=self.extra_options,
  File "/home/airflow/.local/lib/python3.7/site-packages/airflow/providers/http/hooks/http.py", line 128, in run
    session = self.get_conn(headers)
  File "/home/airflow/.local/lib/python3.7/site-packages/airflow/providers/http/hooks/http.py", line 82, in get_conn
    conn = self.get_connection(self.http_conn_id)
  File "/home/airflow/.local/lib/python3.7/site-packages/airflow/hooks/base.py", line 67, in get_connection
    conn = Connection.get_connection_from_secrets(conn_id)
  File "/home/airflow/.local/lib/python3.7/site-packages/airflow/models/connection.py", line 430, in get_connection_from_secrets
    raise AirflowNotFoundException(f"The conn_id `{conn_id}` isn't defined")
airflow.exceptions.AirflowNotFoundException: The conn_id `randomuser_api` isn't defined
[2024-02-05T07:09:47.205+0000] {taskinstance.py:1412} INFO - Marking task as FAILED. dag_id=sqlite_randomuser, task_id=is_api_available, execution_date=20240204T000000, start_date=20240205T070947, end_date=20240205T070947
[2024-02-05T07:09:47.218+0000] {standard_task_runner.py:97} ERROR - Failed to execute job 3 for task is_api_available (The conn_id `randomuser_api` isn't defined; 25977)
[2024-02-05T07:09:47.229+0000] {local_task_job.py:156} INFO - Task exited with return code 1
[2024-02-05T07:09:47.264+0000] {local_task_job.py:279} INFO - 0 downstream tasks scheduled from follow-on schedule check
